<?xml version='1.0' encoding='utf-8'?>
<robot name="arm1_URDF">
    <link name="base">
        <visual name="base_visual">
            <origin xyz="0.0 0.0 0.0" rpy="0.0 0.0 0.0" />
            <geometry>
                <mesh filename="package://final_project/meshes/base.stl" scale="0.001 0.001 0.001" />
            </geometry>
        </visual>
        <collision name="base_collision">
            <origin xyz="0.0 0.0 0.0" rpy="0.0 0.0 0.0" />
            <geometry>
                <mesh filename="package://final_project/meshes/base.stl" scale="0.0009 0.0009 0.0009" />
            </geometry>
        </collision>
    </link>

    <link name="G_50">
        <inertial>
            <origin xyz="-0.051650002701988454 -4.814918927475764e-05 -0.002790728507716764" rpy="0.0 -0.0 0.0" />
            <mass value="1.4023223893809473" />
            <inertia ixx="0.0012741334763335978" iyy="0.001272464352744418" izz="0.0020653341471157383" ixy="8.847089727481716e-17" iyz="-9.523880961507841e-07" ixz="-2.770252915355874e-17" />
        </inertial>
        <visual name="G_50_visual">
            <origin xyz="-0.05165000270197695 -3.750249621958801e-09 0.01300000020128298" rpy="-1.4119781732713213e-14 3.5247026839031876e-16 3.141592653589793" />
            <geometry>
                <mesh filename="package://final_project/meshes/G_50.stl" scale="0.001 0.001 0.001" />
            </geometry>
        </visual>
        </link>

    <link name="G_4">
        <inertial>
            <origin xyz="0.05935499319035209 0.004031725154343588 4.315289153140612e-06" rpy="0.0 -0.0 0.0" />
            <mass value="2.4058767362541364" />
            <inertia ixx="0.00254613790500402" iyy="0.007471226648819496" izz="0.006480794930182138" ixy="-0.00042671993814662407" iyz="-2.6220205331592417e-07" ixz="-5.712604365659679e-07" />
        </inertial>
        <visual name="G_4_visual">
            <origin xyz="-0.06519999979871717 -3.750249686906848e-09 2.7019765980185186e-09" rpy="-3.141592653589793 -5.163040450613385e-30 -3.8424124992884325e-16" />
            <geometry>
                <mesh filename="package://final_project/meshes/G_4.stl" scale="0.001 0.001 0.001" />
            </geometry>
        </visual>
        <collision name="G_4_collision">
            <origin xyz="-0.06519999979871717 -3.750249686906848e-09 2.7019765980185186e-09" rpy="-3.141592653589793 -5.163040450613385e-30 -3.8424124992884325e-16" />
            <geometry>
                <mesh filename="package://final_project/meshes/G_4.stl" scale="0.0009 0.0009 0.0009" />
            </geometry>
        </collision>
    </link>

    <link name="G_2">
        <inertial>
            <origin xyz="-4.8145237741863414e-05 0.05165000270198917 -0.002790724958750035" rpy="0.0 -0.0 0.0" />
            <mass value="1.4023223893809473" />
            <inertia ixx="0.001272464352744418" iyy="0.0012741334763336012" izz="0.0020653341471157383" ixy="-1.110223053643625e-16" iyz="2.081909243396548e-17" ixz="-9.523880961507841e-07" />
        </inertial>
        <visual name="G_2_visual">
            <origin xyz="2.0128346989167768e-10 0.05165000270197766 0.01300000375024975" rpy="2.1137605554777422e-15 7.4824881293612875e-16 1.5707963267948968" />
            <geometry>
                <mesh filename="package://final_project/meshes/G_2.stl" scale="0.001 0.001 0.001" />
            </geometry>
        </visual>
        </link>

    <link name="G_13">
        <inertial>
            <origin xyz="0.01623077756239752 -0.050990561533745905 0.020079991077276673" rpy="0.0 1.2668940227414186e-48 0.0" />
            <mass value="0.41626138634141535" />
            <inertia ixx="0.0004432468996341532" iyy="0.00016897175375006287" izz="0.0004028918180213751" ixy="-3.11176719610465e-05" iyz="4.0510613619287055e-06" ixz="-1.3099358946991532e-06" />
        </inertial>
        <visual name="G_13_visual">
            <origin xyz="2.0125682453908667e-10 -2.6986778323134787e-09 0.018499996249768325" rpy="-3.1415926535897545 2.7586953781964552e-14 1.5707963267948972" />
            <geometry>
                <mesh filename="package://final_project/meshes/G_13.stl" scale="0.001 0.001 0.001" />
            </geometry>
        </visual>
        <collision name="G_13_collision">
            <origin xyz="2.0125682453908667e-10 -2.6986778323134787e-09 0.018499996249768325" rpy="-3.1415926535897545 2.7586953781964552e-14 1.5707963267948972" />
            <geometry>
                <mesh filename="package://final_project/meshes/G_13.stl" scale="0.0008 0.0008 0.0008" />
            </geometry>
        </collision>
    </link>

    <link name="G_5">
        <visual><geometry><mesh filename="package://final_project/meshes/G_5.stl" scale="0.001 0.001 0.001"/></geometry></visual>
        <collision><geometry><mesh filename="package://final_project/meshes/G_5.stl" scale="0.0009 0.0009 0.0009"/></geometry></collision>
    </link>
    <link name="G_7">
        <visual><geometry><mesh filename="package://final_project/meshes/G_7.stl" scale="0.001 0.001 0.001"/></geometry></visual>
        <collision><geometry><mesh filename="package://final_project/meshes/G_7.stl" scale="0.0009 0.0009 0.0009"/></geometry></collision>
    </link>
    <link name="G_25">
        <visual><geometry><mesh filename="package://final_project/meshes/G_25.stl" scale="0.001 0.001 0.001"/></geometry></visual>
        <collision><geometry><mesh filename="package://final_project/meshes/G_25.stl" scale="0.0009 0.0009 0.0009"/></geometry></collision>
    </link>
    <link name="G_27">
        <visual><geometry><mesh filename="package://final_project/meshes/G_27.stl" scale="0.001 0.001 0.001"/></geometry></visual>
        <collision><geometry><mesh filename="package://final_project/meshes/G_27.stl" scale="0.0009 0.0009 0.0009"/></geometry></collision>
    </link>
    <link name="G_28">
        <visual><geometry><mesh filename="package://final_project/meshes/G_28.stl" scale="0.001 0.001 0.001"/></geometry></visual>
        <collision><geometry><mesh filename="package://final_project/meshes/G_28.stl" scale="0.0009 0.0009 0.0009"/></geometry></collision>
    </link>

    <joint name="강체-21" type="fixed">
        <origin xyz="0.0998 -0.020625 -0.051650000000000064" rpy="1.5707963267948966 0 0" />
        <parent link="G_4" />
        <child link="G_2" />
    </joint>

    <joint name="회전-22" type="continuous">
        <origin xyz="-3.552713678800501e-17 0.051650000000000064 0.019750000000000004" rpy="-1.5707963267948966 0 0" />
        <parent link="G_2" />
        <child link="G_5" />
        <axis xyz="0 1 0" />
    </joint>

    <joint name="회전-23" type="continuous">
        <origin xyz="-0.0001249999999999929 0.039 0.19194999999999993" rpy="3.1415926535897913 1.5707963267948966 0" />
        <parent link="G_5" />
        <child link="G_7" />
        <axis xyz="1 0 0" />
    </joint>

    <joint name="회전-24" type="continuous">
        <origin xyz="-0.05755000000000066 0 -0.04" rpy="3.141592653589793 1.5707963267948841 0" />
        <parent link="G_7" />
        <child link="G_25" />
        <axis xyz="-1 0 0" />
    </joint>

    <joint name="회전-25" type="continuous">
        <origin xyz="-0.04 0.0 0.24949997999999995" rpy="3.141592653589793 0 0" />
        <parent link="G_25" />
        <child link="G_27" />
        <axis xyz="0 0 1" />
    </joint>

    <joint name="회전-26" type="continuous">
        <origin xyz="0.017250000000000015 0 -0.05025000000000006" rpy="0 -1.5707963267948966 0" />
        <parent link="G_27" />
        <child link="G_28" />
        <axis xyz="0 0 1" />
    </joint>

    <joint name="회전-28" type="continuous">
        <origin xyz="-0.0507500000000001 0.02025 0.004250000000000007" rpy="1.570796326794911 1.5707963267948746 0" />
        <parent link="G_28" />
        <child link="G_13" />
        <axis xyz="0 0 1" />
    </joint>

    <joint name="강체-29" type="fixed">
        <origin xyz="0.09099999979871715 0 1.0266500027019778" rpy="-3.141592653589793 -1.5707963267948966 0" />
        <parent link="base" />
        <child link="G_50" />
    </joint>

    <joint name="회전-30" type="continuous">
        <origin xyz="-0.051650000000000064 0.0 0.019749999999999997" rpy="0 -1.5707963267948966 0" />
        <parent link="G_50" />
        <child link="G_4" />
        <axis xyz="-1 0 0" />
    </joint>

    <ros2_control name="FakeSystem" type="system">
        <hardware><plugin>mock_components/GenericSystem</plugin></hardware>
        <joint name="회전-30"><command_interface name="position"/><state_interface name="position"><param name="initial_value">0.0</param></state_interface></joint>
        <joint name="회전-22"><command_interface name="position"/><state_interface name="position"><param name="initial_value">0.0</param></state_interface></joint>
        <joint name="회전-23"><command_interface name="position"/><state_interface name="position"><param name="initial_value">0.0</param></state_interface></joint>
        <joint name="회전-24"><command_interface name="position"/><state_interface name="position"><param name="initial_value">0.0</param></state_interface></joint>
        <joint name="회전-25"><command_interface name="position"/><state_interface name="position"><param name="initial_value">0.0</param></state_interface></joint>
        <joint name="회전-26"><command_interface name="position"/><state_interface name="position"><param name="initial_value">0.0</param></state_interface></joint>
        <joint name="회전-28"><command_interface name="position"/><state_interface name="position"><param name="initial_value">0.0</param></state_interface></joint>
    </ros2_control>
</robot>