<?xml version='1.0' encoding='utf-8'?>
<robot name="arm1_URDF">
    <material name="white">
        <color rgba="1.0 1.0 1.0 1.0"/>
    </material>

    <link name="base">
        <visual name="base_visual">
            <origin xyz="0.0 0.0 0.0" rpy="0.0 0.0 0.0" />
            <geometry>
                <mesh filename="package://final_project/meshes/base.stl" scale="0.001 0.001 0.001" />
            </geometry>
            <material name="white"/> </visual>
        <collision name="base_collision">
            <origin xyz="0.0 0.0 0.0" rpy="0.0 0.0 0.0" />
            <geometry>
                <mesh filename="package://final_project/meshes/base.stl" scale="0.001 0.001 0.001" />
            </geometry>
        </collision>
    </link>

    <link name="G_2">
        <inertial>
            <origin xyz="-4.8145237741863414e-05 0.05165000270198917 -0.002790724958750035" rpy="0.0 -0.0 0.0" />
            <mass value="1.4023223893809473" />
            <inertia ixx="0.001272464352744418" iyy="0.0012741334763336012" izz="0.0020653341471157383" ixy="-1.110223053643625e-16" iyz="2.081909243396548e-17" ixz="-9.523880961390572e-07" />
        </inertial>
        <visual name="G_2_visual">
            <origin xyz="2.0128346989167768e-10 0.05165000270197766 0.01300000375024975" rpy="2.1137605554777422e-15 7.4824881293612875e-16 1.5707963267948968" />
            <geometry>
                <mesh filename="package://final_project/meshes/G_2.stl" scale="0.001 0.001 0.001" />
            </geometry>
            <material name="white"/> </visual>
        <collision name="G_2_collision">
            <origin xyz="2.0128346989167768e-10 0.05165000270197766 0.01300000375024975" rpy="2.1137605554777422e-15 7.4824881293612875e-16 1.5707963267948968" />
            <geometry>
                <mesh filename="package://final_project/meshes/G_2.stl" scale="0.001 0.001 0.001" />
            </geometry>
        </collision>
    </link>

    <link name="G_4">
        <inertial>
            <origin xyz="0.05935499319035209 0.004031725154343588 4.315289153140612e-06" rpy="0.0 -0.0 0.0" />
            <mass value="2.4058767362541364" />
            <inertia ixx="0.00254613790500402" iyy="0.007471226648819496" izz="0.006480794930182138" ixy="-0.00042671993814662407" iyz="-2.6220205331592417e-07" ixz="-5.712604365659679e-07" />
        </inertial>
        <visual name="G_4_visual">
            <origin xyz="-0.06519999979871717 -3.750249686906848e-09 2.7019765980185186e-09" rpy="-3.141592653589793 -5.163040450613385e-30 -3.8424124992884325e-16" />
            <geometry>
                <mesh filename="package://final_project/meshes/G_4.stl" scale="0.001 0.001 0.001" />
            </geometry>
            <material name="white"/> </visual>
        <collision name="G_4_collision">
            <origin xyz="-0.06519999979871717 -3.750249686906848e-09 2.7019765980185186e-09" rpy="-3.141592653589793 -5.163040450613385e-30 -3.8424124992884325e-16" />
            <geometry>
                <mesh filename="package://final_project/meshes/G_4.stl" scale="0.001 0.001 0.001" />
            </geometry>
        </collision>
    </link>

    <link name="G_5">
        <inertial>
            <origin xyz="-5.7580882307952665e-05 0.039280374970969485 0.08083082075167425" rpy="0.0 -0.0 0.0" />
            <mass value="3.466326586867893" />
            <inertia ixx="0.01833231958242143" iyy="0.016487101144509797" izz="0.006248046731958307" ixy="-2.1662482159196667e-08" iyz="4.07321564180425e-05" ixz="1.1403774099583153e-05" />
        </inertial>
        <visual name="G_5_visual">
            <origin xyz="2.0128354094595124e-10 0.04037499624975049 -0.16054999729802374" rpy="-3.1415926535897913 -1.5707963267948957 0" />
            <geometry>
                <mesh filename="package://final_project/meshes/G_5.stl" scale="0.001 0.001 0.001" />
            </geometry>
            <material name="white"/> </visual>
        <collision name="G_5_collision">
            <origin xyz="2.0128354094595124e-10 0.04037499624975049 -0.16054999729802374" rpy="-3.1415926535897913 -1.5707963267948957 0" />
            <geometry>
                <mesh filename="package://final_project/meshes/G_5.stl" scale="0.001 0.001 0.001" />
            </geometry>
        </collision>
    </link>

    <link name="G_7">
        <inertial>
            <origin xyz="-0.03998592210060096 -3.6356901924380903e-06 -0.002861891143963007" rpy="-3.589353794432332e-78 -0.0 0.0" />
            <mass value="2.368980623912673" />
            <inertia ixx="0.0019416311242154427" iyy="0.003355777604337584" izz="0.003523029622525935" ixy="2.4541574842760787e-07" iyz="2.145374126797002e-07" ixz="-0.0001750406574957637" />
        </inertial>
        <visual name="G_7_visual">
            <origin xyz="-0.057550002701976695 3.750245075595515e-09 -0.011500000201280365" rpy="3.141592653589793 -1.10361217236557e-15 -1.5707963267948697" />
            <geometry>
                <mesh filename="package://final_project/meshes/G_7.stl" scale="0.001 0.001 0.001" />
            </geometry>
            <material name="white"/> </visual>
        <collision name="G_7_collision">
            <origin xyz="-0.057550002701976695 3.750245075595515e-09 -0.011500000201280365" rpy="3.141592653589793 -1.10361217236557e-15 -1.5707963267948697" />
            <geometry>
                <mesh filename="package://final_project/meshes/G_7.stl" scale="0.001 0.001 0.001" />
            </geometry>
        </collision>
    </link>

    <link name="G_13">
        <inertial>
            <origin xyz="0.01623077756239752 -0.050990561533745905 0.020079991077276673" rpy="0.0 1.2668940227414186e-48 0.0" />
            <mass value="0.41626138634141535" />
            <inertia ixx="0.0004432468996341532" iyy="0.00016897175375006287" izz="0.0004028918180213751" ixy="-3.11176719610465e-05" iyz="4.0510613619287055e-06" ixz="-1.3099358946991532e-06" />
        </inertial>
        <visual name="G_13_visual">
            <origin xyz="2.0125682453908667e-10 -2.6986778323134787e-09 0.018499996249768325" rpy="-3.1415926535897545 2.7586953781964552e-14 1.5707963267948972" />
            <geometry>
                <mesh filename="package://final_project/meshes/G_13.stl" scale="0.001 0.001 0.001" />
            </geometry>
            <material name="white"/> </visual>
        <collision name="G_13_collision">
            <origin xyz="2.0125682453908667e-10 -2.6986778323134787e-09 0.018499996249768325" rpy="-3.1415926535897545 2.7586953781964552e-14 1.5707963267948972" />
            <geometry>
                <mesh filename="package://final_project/meshes/G_13.stl" scale="0.001 0.001 0.001" />
            </geometry>
        </collision>
    </link>

    <link name="G_25">
        <inertial>
            <origin xyz="-0.04021770217309118 3.594903811657252e-05 0.11308873190424187" rpy="0.0 -0.0 0.0" />
            <mass value="3.9257219266470815" />
            <inertia ixx="0.031008283294245542" iyy="0.032519063409173654" izz="0.006387139438659789" ixy="-6.178516376298404e-08" iyz="3.4212091688482806e-05" ixz="-9.652927935599465e-05" />
        </inertial>
        <visual name="G_25_visual">
            <origin xyz="-0.20042499979871867 0.0013749962497433582 -0.25704999729802425" rpy="3.1415926535897665 4.567492924801194e-16 -5.1174342541353607e-17" />
            <geometry>
                <mesh filename="package://final_project/meshes/G_25.stl" scale="0.001 0.001 0.001" />
            </geometry>
            <material name="white"/> </visual>
        <collision name="G_25_collision">
            <origin xyz="-0.20042499979871867 0.0013749962497433582 -0.25704999729802425" rpy="3.1415926535897665 4.567492924801194e-16 -5.1174342541353607e-17" />
            <geometry>
                <mesh filename="package://final_project/meshes/G_25.stl" scale="0.001 0.001 0.001" />
            </geometry>
        </collision>
    </link>

    <link name="G_27">
        <inertial>
            <origin xyz="4.24878932776096e-06 -3.6955642726543836e-08 -0.021545386615044605" rpy="0.0 -0.0 0.0" />
            <mass value="1.031862602100711" />
            <inertia ixx="0.0006021549368913082" iyy="0.0005618534325824154" izz="0.0004886525498680738" ixy="9.417161508603644e-10" iyz="-1.169084286841672e-10" ixz="4.453147348092709e-08" />
        </inertial>
        <visual name="G_27_visual">
            <origin xyz="-0.16042499979872615 -0.0013749962497555976 0.4026999973013231" rpy="-2.6664811242653585e-14 1.3305674229158715e-16 7.892991815695737e-17" />
            <geometry>
                <mesh filename="package://final_project/meshes/G_27.stl" scale="0.001 0.001 0.001" />
            </geometry>
            <material name="white"/> </visual>
        <collision name="G_27_collision">
            <origin xyz="-0.16042499979872615 -0.0013749962497555976 0.4026999973013231" rpy="-2.6664811242653585e-14 1.3305674229158715e-16 7.892991815695737e-17" />
            <geometry>
                <mesh filename="package://final_project/meshes/G_27.stl" scale="0.001 0.001 0.001" />
            </geometry>
        </collision>
    </link>

    <link name="G_28">
        <inertial>
            <origin xyz="-0.068347930458783 -0.00019460842477868307 0.029549211332298847" rpy="-3.067013772411597e-121 -0.0 0.0" />
            <mass value="0.8916811263276078" />
            <inertia ixx="0.0005694478303693226" iyy="0.0018081931798489266" izz="0.0015723146734181888" ixy="4.6348577789113733e-07" iyz="-5.373036988277966e-06" ixz="0.00035615545917725425" />
        </inertial>
        <visual name="G_28_visual">
            <origin xyz="0.4529499973013176 -0.0013749962497559382 0.17742499979873572" rpy="-2.7592757999390442e-14 1.570796326794874 0" />
            <geometry>
                <mesh filename="package://final_project/meshes/G_28.stl" scale="0.001 0.001 0.001" />
            </geometry>
            <material name="white"/> </visual>
        <collision name="G_28_collision">
            <origin xyz="0.4529499973013176 -0.0013749962497559382 0.17742499979873572" rpy="-2.7592757999390442e-14 1.570796326794874 0" />
            <geometry>
                <mesh filename="package://final_project/meshes/G_28.stl" scale="0.001 0.001 0.001" />
            </geometry>
        </collision>
    </link>

    <link name="G_50">
        <inertial>
            <origin xyz="-0.051650002701988454 -4.814918927475764e-05 -0.002790728507716764" rpy="0.0 -0.0 0.0" />
            <mass value="1.4023223893809473" />
            <inertia ixx="0.0012741334763335978" iyy="0.001272464352744418" izz="0.0020653341471157383" ixy="8.847089727481716e-17" iyz="-9.523880961507841e-07" ixz="-2.770252915355874e-17" />
        </inertial>
        <visual name="G_50_visual">
            <origin xyz="-0.051650002701976695 -3.750249621958801e-09 0.01300000020128298" rpy="-1.4119781732713213e-14 3.5247026839031876e-16 3.141592653589793" />
            <geometry>
                <mesh filename="package://final_project/meshes/G_50.stl" scale="0.001 0.001 0.001" />
            </geometry>
            <material name="white"/> </visual>
        <collision name="G_50_collision">
            <origin xyz="-0.051650002701976695 -3.750249621958801e-09 0.01300000020128298" rpy="-1.4119781732713213e-14 3.5247026839031876e-16 3.141592653589793" />
            <geometry>
                <mesh filename="package://final_project/meshes/G_50.stl" scale="0.001 0.001 0.001" />
            </geometry>
        </collision>
    </link>

    <joint name="강체-21" type="fixed">
        <origin xyz="0.0998 -0.020625 -0.051650000000000064" rpy="1.5707963267948966 4.930380657631324e-32 9.041975947780647e-48" />
        <parent link="G_4" />
        <child link="G_2" />
    </joint>

    <joint name="회전-22" type="continuous">
        <origin xyz="-3.552713678800501e-17 0.051650000000000064 0.019750000000000004" rpy="-1.5707963267948966 -9.041975947780647e-48 2.7550144169516306e-65" />
        <parent link="G_2" />
        <child link="G_5" />
        <axis xyz="-0.0 1.0 4.5415775653176777e-32" />
    </joint>

    <joint name="회전-23" type="continuous">
        <origin xyz="-0.0001249999999999929 0.039 0.19194999999999993" rpy="3.1415926535897913 1.5707963267948966 0" />
        <parent link="G_5" />
        <child link="G_7" />
        <axis xyz="1.0 -6.91019838872938e-32 -1.2351231148954849e-14" />
    </joint>

    <joint name="회전-24" type="continuous">
        <origin xyz="-0.05755000000000066 7.382983113757291e-17 -0.04" rpy="3.141592653589793 1.5707963267948841 0" />
        <parent link="G_7" />
        <child link="G_25" />
        <axis xyz="-1.0 -0.0 -1.0579247490760367e-31" />
    </joint>

    <joint name="회전-25" type="continuous">
        <origin xyz="-0.04 0.0 0.24949997999999995" rpy="3.141592653589793 -5.555580851020513e-31 -1.70453562458216e-33" />
        <parent link="G_25" />
        <child link="G_27" />
        <axis xyz="0.0 -2.6982744187943636e-18 1.0" />
    </joint>

    <joint name="회전-26" type="continuous">
        <origin xyz="0.017250000000000015 2.7755575615628914e-19 -0.05025000000000006" rpy="2.0264192044396204e-30 -1.5707963267948966 0" />
        <parent link="G_27" />
        <child link="G_28" />
        <axis xyz="0.0 1.9888065789143055e-30 0.9999999999999999" />
    </joint>

    <joint name="회전-28" type="continuous">
        <origin xyz="-0.0507500000000001 0.02025 0.004250000000000007" rpy="1.570796326794911 1.5707963267948746 0" />
        <parent link="G_28" />
        <child link="G_13" />
        <axis xyz="-1.2408751811923e-32 1.4417991576258236e-14 1.0" />
    </joint>

    <joint name="강체-29" type="fixed">
        <origin xyz="0.09099999979871715 -3.750249421563545e-09 1.0266500027019778" rpy="-3.141592653589793 -1.5707963267948966 0" />
        <parent link="base" />
        <child link="G_50" />
    </joint>

    <joint name="회전-30" type="continuous">
        <origin xyz="-0.051650000000000064 0.0 0.019749999999999997" rpy="5.026394152510874e-33 -1.5707963267948966 0" />
        <parent link="G_50" />
        <child link="G_4" />
        <axis xyz="-1.0 0.0 0.0" />
    </joint>

    <ros2_control name="FakeSystem" type="system">
        <hardware>
            <plugin>mock_components/GenericSystem</plugin>
        </hardware>
        <joint name="회전-30">
            <command_interface name="position"/>
            <state_interface name="position"><param name="initial_value">0.0</param></state_interface>
            <state_interface name="velocity"/>
        </joint>
        <joint name="회전-22">
            <command_interface name="position"/>
            <state_interface name="position"><param name="initial_value">0.0</param></state_interface>
            <state_interface name="velocity"/>
        </joint>
        <joint name="회전-23">
            <command_interface name="position"/>
            <state_interface name="position"><param name="initial_value">0.0</param></state_interface>
            <state_interface name="velocity"/>
        </joint>
        <joint name="회전-24">
            <command_interface name="position"/>
            <state_interface name="position"><param name="initial_value">0.0</param></state_interface>
            <state_interface name="velocity"/>
        </joint>
        <joint name="회전-25">
            <command_interface name="position"/>
            <state_interface name="position"><param name="initial_value">0.0</param></state_interface>
            <state_interface name="velocity"/>
        </joint>
        <joint name="회전-26">
            <command_interface name="position"/>
            <state_interface name="position"><param name="initial_value">0.0</param></state_interface>
            <state_interface name="velocity"/>
        </joint>
        <joint name="회전-28">
            <command_interface name="position"/>
            <state_interface name="position"><param name="initial_value">0.0</param></state_interface>
            <state_interface name="velocity"/>
        </joint>
    </ros2_control>
</robot>
